Workbook

Sheet Dashboard de Vendas
A1: DASHBOARD EXECUTIVO DE DESEMPENHO DE VENDAS
A3: Visão Consolidada de Faturamento, Margem de Lucro, Performance por Equipe e Produtos
A5: INDICADORES-CHAVE DE DESEMPENHO (KPIs)
A6: FATURAMENTO TOTAL | D6: LUCRO TOTAL ACUMULADO | G6: MARGEM DE LUCRO MÉDIA | J6: TOTAL DE PEDIDOS / VENDAS
A7: =SUM('Base de Dados'!J2:J151) | D7: =SUM('Base de Dados'!L2:L151) | G7: =D7/A7 | J7: =COUNTA('Base de Dados'!A2:A151)
G26: RANKING DE VENDEDORES (TOP PERFORMANCE)
G27: Vendedor | J27: Faturamento Total (R$)
G28: Ana Silva | J28: =SUMIF('Base de Dados'!E:E, G28, 'Base de Dados'!J:J)
G29: Carlos Souza | J29: =SUMIF('Base de Dados'!E:E, G29, 'Base de Dados'!J:J)
G30: Mariana Oliveira | J30: =SUMIF('Base de Dados'!E:E, G30, 'Base de Dados'!J:J)
G31: Lucas Ferreira | J31: =SUMIF('Base de Dados'!E:E, G31, 'Base de Dados'!J:J)
G32: Beatriz Costa | J32: =SUMIF('Base de Dados'!E:E, G32, 'Base de Dados'!J:J)

Sheet Base de Dados
A1: ID Pedido | B1: Data | C1: Mês/Ano | D1: Região | E1: Vendedor | F1: Categoria | G1: Produto | H1: Qtd | I1: Preço Unit. (R$) | J1: Faturamento (R$) | K1: Custo Total (R$) | L1: Lucro (R$)
A2: PED-1001 | B2: 46186 | C2: 2026-06 | D2: Sudeste | E2: Ana Silva | F2: Acessórios | G2: Webcam Full HD | H2: 4 | I2: 380 | J2: =H2*I2 | K2: =H2*220 | L2: =J2-K2
A3: PED-1002 | B3: 46080 | C3: 2026-02 | D3: Sul | E3: Ana Silva | F3: Acessórios | G3: Teclado Mecânico | H3: 10 | I3: 350 | J3: =H3*I3 | K3: =H3*200 | L3: =J3-K3
A4: PED-1003 | B4: 46131 | C4: 2026-04 | D4: Sudeste | E4: Ana Silva | F4: Eletrônicos | G4: Smartphone 5G | H4: 4 | I4: 2800 | J4: =H4*I4 | K4: =H4*1900 | L4: =J4-K4
A5: PED-1004 | B5: 46152 | C5: 2026-05 | D5: Norte | E5: Ana Silva | F5: Acessórios | G5: Mouse Vertical | H5: 9 | I5: 220 | J5: =H5*I5 | K5: =H5*120 | L5: =J5-K5
A6: PED-1005 | B6: 46130 | C6: 2026-04 | D6: Sul | E6: Lucas Ferreira | F6: Acessórios | G6: Webcam Full HD | H6: 1 | I6: 380 | J6: =H6*I6 | K6: =H6*220 | L6: =J6-K6
A7: PED-1006 | B7: 46217 | C7: 2026-07 | D7: Sul | E7: Lucas Ferreira | F7: Móveis | G7: Mesa Escritório L | H7: 3 | I7: 950 | J7: =H7*I7 | K7: =H7*600 | L7: =J7-K7
A8: PED-1007 | B8: 46078 | C8: 2026-02 | D8: Nordeste | E8: Ana Silva | F8: Eletrônicos | G8: Headset Sem Fio | H8: 2 | I8: 450 | J8: =H8*I8 | K8: =H8*250 | L8: =J8-K8
A9: PED-1008 | B9: 46114 | C9: 2026-04 | D9: Nordeste | E9: Beatriz Costa | F9: Móveis | G9: Cadeira Ergonômica | H9: 8 | I9: 1200 | J9: =H9*I9 | K9: =H9*750 | L9: =J9-K9
A10: PED-1009 | B10: 46160 | C10: 2026-05 | D10: Sudeste | E10: Lucas Ferreira | F10: Eletrônicos | G10: Monitor 27' 144Hz | H10: 10 | I10: 1600 | J10: =H10*I10 | K10: =H10*1100 | L10: =J10-K10
A11: PED-1010 | B11: 46249 | C11: 2026-08 | D11: Nordeste | E11: Beatriz Costa | F11: Eletrônicos | G11: Notebook Gamer | H11: 1 | I11: 4500 | J11: =H11*I11 | K11: =H11*3200 | L11: =J11-K11
A12: PED-1011 | B12: 46192 | C12: 2026-06 | D12: Sul | E12: Mariana Oliveira | F12: Eletrônicos | G12: Smartphone 5G | H12: 2 | I12: 2800 | J12: =H12*I12 | K12: =H12*1900 | L12: =J12-K12
A13: PED-1012 | B13: 46120 | C13: 2026-04 | D13: Nordeste | E13: Lucas Ferreira | F13: Acessórios | G13: Webcam Full HD | H13: 3 | I13: 380 | J13: =H13*I13 | K13: =H13*220 | L13: =J13-K13
A14: PED-1013 | B14: 46117 | C14: 2026-04 | D14: Nordeste | E14: Carlos Souza | F14: Acessórios | G14: Webcam Full HD | H14: 2 | I14: 380 | J14: =H14*I14 | K14: =H14*220 | L14: =J14-K14
A15: PED-1014 | B15: 46178 | C15: 2026-06 | D15: Sul | E15: Beatriz Costa | F15: Acessórios | G15: Mouse Vertical | H15: 3 | I15: 220 | J15: =H15*I15 | K15: =H15*120 | L15: =J15-K15
A16: PED-1015 | B16: 46141 | C16: 2026-04 | D16: Centro-Oeste | E16: Mariana Oliveira | F16: Acessórios | G16: Mouse Vertical | H16: 6 | I16: 220 | J16: =H16*I16 | K16: =H16*120 | L16: =J16-K16
A17: PED-1016 | B17: 46238 | C17: 2026-08 | D17: Sudeste | E17: Carlos Souza | F17: Eletrônicos | G17: Monitor 27' 144Hz | H17: 7 | I17: 1600 | J17: =H17*I17 | K17: =H17*1100 | L17: =J17-K17
A18: PED-1017 | B18: 46091 | C18: 2026-03 | D18: Sudeste | E18: Carlos Souza | F18: Acessórios | G18: Webcam Full HD | H18: 4 | I18: 380 | J18: =H18*I18 | K18: =H18*220 | L18: =J18-K18
A19: PED-1018 | B19: 46190 | C19: 2026-06 | D19: Centro-Oeste | E19: Lucas Ferreira | F19: Acessórios | G19: Suporte Monitor | H19: 3 | I19: 150 | J19: =H19*I19 | K19: =H19*80 | L19: =J19-K19
A20: PED-1019 | B20: 46090 | C20: 2026-03 | D20: Sul | E20: Carlos Souza | F20: Acessórios | G20: Webcam Full HD | H20: 10 | I20: 380 | J20: =H20*I20 | K20: =H20*220 | L20: =J20-K20
A21: PED-1020 | B21: 46132 | C21: 2026-04 | D21: Norte | E21: Lucas Ferreira | F21: Móveis | G21: Cadeira Ergonômica | H21: 3 | I21: 1200 | J21: =H21*I21 | K21: =H21*750 | L21: =J21-K21
A22: PED-1021 | B22: 46153 | C22: 2026-05 | D22: Centro-Oeste | E22: Ana Silva | F22: Eletrônicos | G22: Notebook Gamer | H22: 3 | I22: 4500 | J22: =H22*I22 | K22: =H22*3200 | L22: =J22-K22
A23: PED-1022 | B23: 46183 | C23: 2026-06 | D23: Sul | E23: Lucas Ferreira | F23: Acessórios | G23: Teclado Mecânico | H23: 7 | I23: 350 | J23: =H23*I23 | K23: =H23*200 | L23: =J23-K23
A24: PED-1023 | B24: 46120 | C24: 2026-04 | D24: Norte | E24: Lucas Ferreira | F24: Acessórios | G24: Webcam Full HD | H24: 9 | I24: 380 | J24: =H24*I24 | K24: =H24*220 | L24: =J24-K24
A25: PED-1024 | B25: 46243 | C25: 2026-08 | D25: Sudeste | E25: Ana Silva | F25: Acessórios | G25: Webcam Full HD | H25: 6 | I25: 380 | J25: =H25*I25 | K25: =H25*220 | L25: =J25-K25
A26: PED-1025 | B26: 46051 | C26: 2026-01 | D26: Nordeste | E26: Lucas Ferreira | F26: Eletrônicos | G26: Headset Sem Fio | H26: 1 | I26: 450 | J26: =H26*I26 | K26: =H26*250 | L26: =J26-K26
A27: PED-1026 | B27: 46207 | C27: 2026-07 | D27: Nordeste | E27: Beatriz Costa | F27: Eletrônicos | G27: Notebook Gamer | H27: 5 | I27: 4500 | J27: =H27*I27 | K27: =H27*3200 | L27: =J27-K27
A28: PED-1027 | B28: 46238 | C28: 2026-08 | D28: Norte | E28: Beatriz Costa | F28: Eletrônicos | G28: Smartphone 5G | H28: 6 | I28: 2800 | J28: =H28*I28 | K28: =H28*1900 | L28: =J28-K28
A29: PED-1028 | B29: 46218 | C29: 2026-07 | D29: Sul | E29: Beatriz Costa | F29: Acessórios | G29: Teclado Mecânico | H29: 10 | I29: 350 | J29: =H29*I29 | K29: =H29*200 | L29: =J29-K29
A30: PED-1029 | B30: 46105 | C30: 2026-03 | D30: Centro-Oeste | E30: Ana Silva | F30: Eletrônicos | G30: Monitor 27' 144Hz | H30: 5 | I30: 1600 | J30: =H30*I30 | K30: =H30*1100 | L30: =J30-K30
A31: PED-1030 | B31: 46084 | C31: 2026-03 | D31: Sudeste | E31: Carlos Souza | F31: Acessórios | G31: Teclado Mecânico | H31: 2 | I31: 350 | J31: =H31*I31 | K31: =H31*200 | L31: =J31-K31
A32: PED-1031 | B32: 46210 | C32: 2026-07 | D32: Centro-Oeste | E32: Ana Silva | F32: Acessórios | G32: Mouse Vertical | H32: 3 | I32: 220 | J32: =H32*I32 | K32: =H32*120 | L32: =J32-K32
A33: PED-1032 | B33: 46191 | C33: 2026-06 | D33: Centro-Oeste | E33: Beatriz Costa | F33: Eletrônicos | G33: Monitor 27' 144Hz | H33: 9 | I33: 1600 | J33: =H33*I33 | K33: =H33*1100 | L33: =J33-K33
A34: PED-1033 | B34: 46246 | C34: 2026-08 | D34: Norte | E34: Lucas Ferreira | F34: Eletrônicos | G34: Smartphone 5G | H34: 5 | I34: 2800 | J34: =H34*I34 | K34: =H34*1900 | L34: =J34-K34
A35: PED-1034 | B35: 46125 | C35: 2026-04 | D35: Nordeste | E35: Lucas Ferreira | F35: Acessórios | G35: Suporte Monitor | H35: 2 | I35: 150 | J35: =H35*I35 | K35: =H35*80 | L35: =J35-K35
A36: PED-1035 | B36: 46086 | C36: 2026-03 | D36: Sul | E36: Ana Silva | F36: Móveis | G36: Cadeira Ergonômica | H36: 10 | I36: 1200 | J36: =H36*I36 | K36: =H36*750 | L36: =J36-K36
A37: PED-1036 | B37: 46164 | C37: 2026-05 | D37: Sul | E37: Beatriz Costa | F37: Eletrônicos | G37: Notebook Gamer | H37: 2 | I37: 4500 | J37: =H37*I37 | K37: =H37*3200 | L37: =J37-K37
A38: PED-1037 | B38: 46204 | C38: 2026-07 | D38: Sudeste | E38: Carlos Souza | F38: Eletrônicos | G38: Notebook Gamer | H38: 6 | I38: 4500 | J38: =H38*I38 | K38: =H38*3200 | L38: =J38-K38
A39: PED-1038 | B39: 46041 | C39: 2026-01 | D39: Norte | E39: Carlos Souza | F39: Móveis | G39: Estante de Livros | H39: 8 | I39: 500 | J39: =H39*I39 | K39: =H39*300 | L39: =J39-K39
A40: PED-1039 | B40: 46077 | C40: 2026-02 | D40: Norte | E40: Carlos Souza | F40: Acessórios | G40: Suporte Monitor | H40: 4 | I40: 150 | J40: =H40*I40 | K40: =H40*80 | L40: =J40-K40
...

Sheet Parâmetros
A1: RESUMO POR VENDEDOR | D1: RESUMO POR CATEGORIA | G1: RESUMO POR REGIÃO
A2: Vendedor | B2: Total Faturamento (R$) | D2: Categoria | E2: Total Faturamento (R$) | G2: Região | H2: Total Faturamento (R$)
A3: Ana Silva | B3: =SUMIF('Base de Dados'!E:E, A3, 'Base de Dados'!J:J) | D3: Eletrônicos | E3: =SUMIF('Base de Dados'!F:F, D3, 'Base de Dados'!J:J) | G3: Sudeste | H3: =SUMIF('Base de Dados'!D:D, G3, 'Base de Dados'!J:J)
A4: Carlos Souza | B4: =SUMIF('Base de Dados'!E:E, A4, 'Base de Dados'!J:J) | D4: Móveis | E4: =SUMIF('Base de Dados'!F:F, D4, 'Base de Dados'!J:J) | G4: Sul | H4: =SUMIF('Base de Dados'!D:D, G4, 'Base de Dados'!J:J)
A5: Mariana Oliveira | B5: =SUMIF('Base de Dados'!E:E, A5, 'Base de Dados'!J:J) | D5: Acessórios | E5: =SUMIF('Base de Dados'!F:F, D5, 'Base de Dados'!J:J) | G5: Nordeste | H5: =SUMIF('Base de Dados'!D:D, G5, 'Base de Dados'!J:J)
A6: Lucas Ferreira | B6: =SUMIF('Base de Dados'!E:E, A6, 'Base de Dados'!J:J) | G6: Centro-Oeste | H6: =SUMIF('Base de Dados'!D:D, G6, 'Base de Dados'!J:J)
A7: Beatriz Costa | B7: =SUMIF('Base de Dados'!E:E, A7, 'Base de Dados'!J:J) | G7: Norte | H7: =SUMIF('Base de Dados'!D:D, G7, 'Base de Dados'!J:J)
